<?xml version="1.0"?>
<robot name="origins">
  <link name="base_link">
    <visual>
      <geometry>
        <box size="0.2 0.4 0.6"/>
      </geometry>
    </visual>
  </link>

  <link name="right_leg">
    <visual>
      <geometry>
        <cylinder length="0.6" radius="0.1"/>     
      </geometry>
      <origin rpy="0 0 0" xyz="0 0.5 0"/>
    </visual>
  </link>

  <joint name="base_to_right_leg" type="continuous">
    <parent link="base_link"/>
    <child link="right_leg"/>
    <origin xyz="0 -0.2 0"/>
    <axis xyz="0 1 0"/>
  </joint>

</robot>
